Workbook

Sheet Fertilizante
A1: PRODUTO | C1: DOSE/HÁ | D1: PREÇO | E1: Embalagem
A2: 00-19-00 | B2: FERTILIZANTE | C2: 200 | D2: 320 | E2: 1
A3: 00-32-00 | B3: FERTILIZANTE | C3: 0 | D3: 400 | E3: 1
A4: 02-20-20 | B4: FERTILIZANTE | C4: 0 | D4: 425 | E4: 1
A5: 04-30-10 | B5: FERTILIZANTE | C5: 0 | D5: 435 | E5: 1
A6: 05-25-25 | B6: FERTILIZANTE | C6: 0 | D6: 480 | E6: 1
A7: 06-30-06 | B7: FERTILIZANTE | C7: 0 | D7: 430 | E7: 1
A8: 08-20-10 | B8: FERTILIZANTE | C8: 0 | D8: 420 | E8: 1
A9: KCL | B9: FERTILIZANTE | C9: 0.1 | D9: 460 | E9: 1

Sheet Sementes
A1: SEM SOJA 63I64RSF IPRO S/T - (5,5) | B1: SEMENTE | D1: 1.2633687 | E1: 25
A2: SEM SOJA 63I64RSF IPRO S/T - (6,5) | B2: SEMENTE | D2: 1.0030382 | E2: 25
A3: SEM SOJA 63I64RSF IPRO + TSI + INOCULANTE - (5,5) | B3: SEMENTE | D3: 1.94 | E3: 25
A4: SEM SOJA 63I64RSF IPRO + TSI + INOCULANTE - (6,5) | B4: SEMENTE | D4: 1.66 | E4: 25
A5: SEM SOJA BS 2606 S/T - (5,5) | B5: SEMENTE | D5: 1.2 | E5: 25
A6: SEM SOJA BS 2606 S/T - (6,5) | B6: SEMENTE | D6: 0.91115685 | E6: 25
A7: SEM SOJA BS 2606 TSI + TSI + INOCULANTE - (5,5) | B7: SEMENTE | D7: 1.75 | E7: 25
A8: SEM SOJA BS 2606 TSI + TSI + INOCULANTE - (6,5) | B8: SEMENTE | D8: 1.5236993 | E8: 25
A9: SEM SOJA M5947IPRO S/T - (5,5) | B9: SEMENTE | C9: 0 | D9: 1.1714874 | E9: 25
A10: SEM SOJA M5947IPRO S/T - (6,5) | B10: SEMENTE | C10: 0 | D10: 0.91115685 | E10: 25
A11: SEM SOJA M5947IPRO TSI + ECOTRICH - (5,5) | B11: SEMENTE | C11: 40 | D11: 1.89 | E11: 25
A12: SEM SOJA M5947IPRO TSI + ECOTRICH - (6,5) | B12: SEMENTE | C12: 0 | D12: 1.66 | E12: 25
A13: SEM SOJA M6210IPRO + TSI+ INOCULANTE - (5,5) | B13: SEMENTE | C13: 0 | D13: 1.81 | E13: 25
A14: SEM SOJA M6210IPRO + TSI+ INOCULANTE - (6,5) | B14: SEMENTE | C14: 0 | D14: 1.56 | E14: 25
A15: SEM SOJA M6210IPRO S/T - (5,5) | B15: SEMENTE | C15: 0 | D15: 1.1408603 | E15: 25
A16: SEM SOJA M6210IPRO S/T - (6,5) | B16: SEMENTE | C16: 0 | D16: 0.91115685 | E16: 25
A17: SEM SOJA M6410 + TSI + INOCULANTE - (5,5) | B17: SEMENTE | C17: 0 | D17: 1.82 | E17: 25
A18: SEM SOJA M6410 + TSI + INOCULANTE - (6,5) | B18: SEMENTE | C18: 0 | D18: 1.57 | E18: 25
A19: SEM SOJA M6410 S/T - (5,5) | B19: SEMENTE | C19: 0 | D19: 1.1714874 | E19: 25
A20: SEM SOJA M6410 S/T - (6,5) | B20: SEMENTE | C20: 0 | D20: 0.94178397 | E20: 25
A21: SEM SOJA NA5909 + TSI + INOCULANTE - (5,5) | B21: SEMENTE | D21: 2.04 | E21: 25
A22: SEM SOJA NA5909 + TSI + INOCULANTE - (6,5) | B22: SEMENTE | D22: 1.82 | E22: 25
A23: SEM SOJA NA5909 S/T - (5,5) | B23: SEMENTE | D23: 1.3512686 | E23: 25
A24: SEM SOJA NA5909 S/T - (6,5) | B24: SEMENTE | D24: 1.1521923 | E24: 25
A25: SEM SOJA TMG 7062 IPRO + TSI +INOCULANTE - (5,5) | B25: SEMENTE | C25: 0 | D25: 2.09 | E25: 25
A26: SEM SOJA TMG 7062 IPRO + TSI +INOCULANTE - (6,5) | B26: SEMENTE | C26: 0 | D26: 1.76 | E26: 25
A27: SEM SOJA TMG 7062 IPRO S/T - (5,5) | B27: SEMENTE | C27: 0 | D27: 1.4014358 | E27: 25
A28: SEM SOJA TMG 7062 IPRO S/T - (6,5) | B28: SEMENTE | C28: 0 | D28: 1.0951646 | E28: 25
A29: SEM SOJA TMG 7262RR + TSI + INOCULANTE - (5,5) | B29: SEMENTE | D29: 2.09 | E29: 25
A30: SEM SOJA TMG 7262RR + TSI + INOCULANTE - (6,5) | B30: SEMENTE | D30: 1.8 | E30: 25
A31: SEM SOJA TMG 7262RR S/T - (5,5) | B31: SEMENTE | D31: 1.4167494 | E31: 25
A32: SEM SOJA TMG 7262RR S/T - (6,5) | B32: SEMENTE | D32: 1.0951646 | E32: 25
A33: SEM SOJA TMG7063IPRO + TSI + INOCULANTE - (5,5) | B33: SEMENTE | D33: 2.14 | E33: 25
A34: SEM SOJA TMG7063IPRO + TSI + INOCULANTE - (6,5) | B34: SEMENTE | D34: 1.77 | E34: 25
A35: SEM SOJA TMG7063IPRO S/T - (5,5) | B35: SEMENTE | D35: 1.4473765 | E35: 25
A36: SEM SOJA TMG7063IPRO S/T - (6,5) | B36: SEMENTE | D36: 1.11 | E36: 25

Sheet Precos
B1: Produtos | C1: Pricipio Ativo | D1: Precio | E1: Embalagem | F1: Custo | G1: Margem | H1: Precio Real | I1: Margem Real | J1: DIF
B2: Fert. 00-00-60 Fertipar C | E2: 1000 | G2: =(D2-F2)/F2 -> #DIV/0! | H2: 0.495 | I2: =(H2-F2)/F2 -> #DIV/0! | J2: =G2-I2 -> #DIV/0! | K2: 0.0018 | L2: =G2-19% -> #DIV/0!
B3: Fert. 02-23-23 TopMix Evo. Yara C | E3: 1000 | G3: =(D3-F3)/F3 -> #DIV/0! | H3: 0.685 | I3: =(H3-F3)/F3 -> #DIV/0! | J3: =G3-I3 -> #DIV/0! | K3: 0.0018 | L3: =G3-19% -> #DIV/0!
B4: Fert. 08-40-08 TopMIx Evo. Yara C | E4: 1000 | G4: =(D4-F4)/F4 -> #DIV/0! | H4: 0.883 | I4: =(H4-F4)/F4 -> #DIV/0! | J4: =G4-I4 -> #DIV/0! | K4: 0.002 | L4: =G4-19% -> #DIV/0!
L5: =G5-19% -> -0.19
B6: 55I57 RSF IPRO (ZEUS) (260mil/Ha) + TSIA | C6: Sem Soja | D6: 63 | E6: 1 | F6: 45.57 | G6: =(D6-F6)/F6 -> 0.38248848 | H6: 50 | I6: =(H6-F6)/F6 -> 0.097213079 | J6: =G6-I6 -> 0.2852754 | K6: 0.025 | L6: =G6-19% -> 0.19248848
B7: 55I57 RSF IPRO (ZEUS) (260mil/Ha) A | C7: Sem Soja | D7: 42 | E7: 1 | F7: 31.89 | G7: =(D7-F7)/F7 -> 0.31702728 | H7: 29.308859 | I7: =(H7-F7)/F7 -> -0.080938898 | J7: =G7-I7 -> 0.39796618 | K7: 0.025 | L7: =G7-19% -> 0.12702728
B8: 63IX65 RSF (COLISEU) (235mil/Há) + TSI A | C8: Sem Soja | D8: 48 | E8: 1 | F8: 34.75 | G8: =(D8-F8)/F8 -> 0.38129496 | I8: =(H8-F8)/F8 -> -1 | J8: =G8-I8 -> 1.381295 | K8: 0.025 | L8: =G8-19% -> 0.19129496
B9: 63IX65 RSF (COLISEU) (235mil/Há) A | C9: Sem Soja | D9: 33.8 | E9: 1 | F9: 24.33 | G9: =(D9-F9)/F9 -> 0.3892314 | H9: 26 | I9: =(H9-F9)/F9 -> 0.06863954 | J9: =G9-I9 -> 0.32059186 | K9: 0.025 | L9: =G9-19% -> 0.1992314
B10: 64I61 RSF IPRO (FIBRA) (235mil/Ha) + TSI A | C10: Sem Soja | D10: 47.5 | E10: 1 | F10: 34.16 | G10: =(D10-F10)/F10 -> 0.39051522 | I10: =(H10-F10)/F10 -> -1 | J10: =G10-I10 -> 1.3905152 | K10: 0.025 | L10: =G10-19% -> 0.20051522
B11: 64I61 RSF IPRO (FIBRA) (235mil/Ha) A | C11: Sem Soja | D11: 33 | E11: 1 | F11: 23.92 | G11: =(D11-F11)/F11 -> 0.37959866 | H11: 25.44899 | I11: =(H11-F11)/F11 -> 0.063920985 | J11: =G11-I11 -> 0.31567768 | K11: 0.025 | L11: =G11-19% -> 0.18959866
B12: 64IX66 RSF (NEXUS) (235mil/Há) + TSI A | C12: Sem Soja | D12: 47.5 | E12: 1 | F12: 34.01 | G12: =(D12-F12)/F12 -> 0.39664804 | I12: =(H12-F12)/F12 -> -1 | J12: =G12-I12 -> 1.396648 | K12: 0.025 | L12: =G12-19% -> 0.20664804
B13: 64IX66 RSF (NEXUS) (235mil/Há) A | C13: Sem Soja | D13: 33 | E13: 1 | F13: 23.81 | G13: =(D13-F13)/F13 -> 0.38597228 | H13: 26 | I13: =(H13-F13)/F13 -> 0.09197816 | J13: =G13-I13 -> 0.29399412 | K13: 0.025 | L13: =G13-19% -> 0.19597228
B14: 65I65 RSF IPRO (COMPACTA) (240mil/Ha) + TSI A | C14: Sem Soja | D14: 55.5 | E14: 1 | F14: 39.9 | G14: =(D14-F14)/F14 -> 0.39097744 | I14: =(H14-F14)/F14 -> -1 | J14: =G14-I14 -> 1.3909774 | K14: 0.025 | L14: =G14-19% -> 0.20097744
B15: 65I65 RSF IPRO (COMPACTA) (240mil/Ha) A | C15: Sem Soja | D15: 39 | E15: 1 | F15: 27.93 | G15: =(D15-F15)/F15 -> 0.39634801 | H15: 30.568693 | I15: =(H15-F15)/F15 -> 0.094475229 | J15: =G15-I15 -> 0.30187278 | K15: 0.025 | L15: =G15-19% -> 0.20634801
B16: DM66I68 RSF IPRO (230mil/Há + TSI A | C16: Sem Soja | D16: 59 | E16: 1 | F16: 42.49 | G16: =(D16-F16)/F16 -> 0.38856201 | I16: =(H16-F16)/F16 -> -1 | J16: =G16-I16 -> 1.388562 | K16: 0.025 | L16: =G16-19% -> 0.19856201
B17: DM66I68 RSF IPRO (230mil/Há A | C17: Sem Soja | D17: 41 | E17: 1 | F17: 29.74 | G17: =(D17-F17)/F17 -> 0.37861466 | H17: 40.018635 | I17: =(H17-F17)/F17 -> 0.3456165 | J17: =G17-I17 -> 0.032998162 | K17: 0.025 | L17: =G17-19% -> 0.18861466
B18: M5921 I2X (240mil/Ha) + TSI A | C18: Sem Soja | D18: 48.5 | E18: 1 | F18: 34.92 | G18: =(D18-F18)/F18 -> 0.38888889 | I18: =(H18-F18)/F18 -> -1 | J18: =G18-I18 -> 1.3888889 | K18: 0.025 | L18: =G18-19% -> 0.19888889
B19: M5921 I2X (240mil/Ha) A | C19: Sem Soja | D19: 34 | E19: 1 | F19: 24.44 | G19: =(D19-F19)/F19 -> 0.39116203 | H19: 28.878671 | I19: =(H19-F19)/F19 -> 0.18161502 | J19: =G19-I19 -> 0.20954701 | K19: 0.025 | L19: =G19-19% -> 0.20116203
B20: M5947 IPRO (240mil/Ha) + TSI A | C20: Sem Soja | D20: 46.8 | E20: 1 | F20: 33.48 | G20: =(D20-F20)/F20 -> 0.39784946 | I20: =(H20-F20)/F20 -> -1 | J20: =G20-I20 -> 1.3978495 | K20: 0.025 | L20: =G20-19% -> 0.20784946
B21: M5947 IPRO (240mil/Ha) A | C21: Sem Soja | D21: 33 | E21: 1 | F21: 23.44 | G21: =(D21-F21)/F21 -> 0.40784983 | H21: 26.942828 | I21: =(H21-F21)/F21 -> 0.14943804 | J21: =G21-I21 -> 0.25841179 | K21: 0.025 | L21: =G21-19% -> 0.21784983
B22: M6130 I2X (230mil/Ha) + TSI A | C22: Sem Soja | D22: 50 | E22: 1 | F22: 36.78 | G22: =(D22-F22)/F22 -> 0.35943448 | I22: =(H22-F22)/F22 -> -1 | J22: =G22-I22 -> 1.3594345 | K22: 0.025 | L22: =G22-19% -> 0.16943448
B23: M6130 I2X (230mil/Ha) A | C23: Sem Soja | D23: 35.5 | E23: 1 | F23: 25.75 | G23: =(D23-F23)/F23 -> 0.37864078 | H23: 25.895723 | I23: =(H23-F23)/F23 -> 0.0056591486 | J23: =G23-I23 -> 0.37298163 | K23: 0.025 | L23: =G23-19% -> 0.18864078
B25: Acrescent Raiz F (2ml/Kg) A | D25: 99 | E25: 5 | F25: 70 | G25: =(D25-F25)/F25 -> 0.41428571 | H25: 99.52 | I25: =(H25-F25)/F25 -> 0.42171429 | J25: =G25-I25 -> -0.0074285714 | K25: 0.04 | L25: =G25-19% -> 0.22428571
B26: Clorante 62,5 (0,5 ml/Kg) A | D26: 90 | E26: 5 | F26: 60 | G26: =(D26-F26)/F26 -> 0.5 | H26: 33 | I26: =(H26-F26)/F26 -> -0.45 | J26: =G26-I26 -> 0.95 | K26: 0.01 | L26: =G26-19% -> 0.31
B27: Dermacor (0,5ml/Kg) C | D27: 198 | E27: 5 | F27: 165 | G27: =(D27-F27)/F27 -> 0.2 | J27: =G27-I27 -> 0.2 | K27: 0.004 | L27: =G27-19% -> 0.01
B28: Ever Gold (0,9ml/Kg) C | D28: 66 | E28: 5 | F28: 53 | G28: =(D28-F28)/F28 -> 0.24528302 | J28: =G28-I28 -> 0.24528302 | K28: 0.004 | L28: =G28-19% -> 0.055283019
B29: Fertactyl Leg (2 ml/kg) A | D29: 107 | E29: 2 | F29: 79 | G29: =(D29-F29)/F29 -> 0.35443038 | H29: 94.53 | I29: =(H29-F29)/F29 -> 0.19658228 | J29: =G29-I29 -> 0.1578481 | K29: 0.04 | L29: =G29-19% -> 0.16443038
B30: Rancona (1 ml/kg) C | C30: Metalaxil 2% + Fludioxonil 2,5% + Tiabendazol 15% | D30: 49.5 | E30: 1 | F30: 42 | G30: =(D30-F30)/F30 -> 0.17857143 | H30: 47 | I30: =(H30-F30)/F30 -> 0.11904762 | J30: =G30-I30 -> 0.05952381 | K30: 0.004 | L30: =G30-19% -> -0.011428571
B31: Rizoderma Max (2 ml/kg + 1 ml/kg) B | C31: Trichoderma harzianum 2 (Th2) Bj Rizoderma de 9lts cada + Protector de 3 L cada. Para 3000 kg de semilla | D31: 66 | E31: 2 | F31: 47.5 | G31: =(D31-F31)/F31 -> 0.38947368 | H31: 58 | I31: =(H31-F31)/F31 -> 0.22105263 | J31: =G31-I31 -> 0.16842105 | K31: 0.04 | L31: =G31-19% -> 0.19947368
B32: Rizoliq Top (2 ml/kg) A | C32: Inoculante soja 2X10a10’ | D32: 26 | E32: 2 | F32: 16 | G32: =(D32-F32)/F32 -> 0.625 | H32: 21 | I32: =(H32-F32)/F32 -> 0.3125 | J32: =G32-I32 -> 0.3125 | K32: 0.04 | L32: =G32-19% -> 0.435
B33: VitaGrow TS (1ml/Kg) A | D33: 72 | E33: 5 | F33: 47 | G33: =(D33-F33)/F33 -> 0.53191489 | H33: 68 | I33: =(H33-F33)/F33 -> 0.44680851 | J33: =G33-I33 -> 0.085106383 | K33: 0.04 | L33: =G33-19% -> 0.34191489
B34: Rizospirilum (2ml/Kg) A | D34: 40 | E34: 2 | F34: 25 | G34: =(D34-F34)/F34 -> 0.6 | H34: 30 | I34: =(H34-F34)/F34 -> 0.2 | J34: =G34-I34 -> 0.4 | K34: 0.04 | L34: =G34-19% -> 0.41
B36: Clomazone 48% (0,8 - 1) C | D36: 9.5 | E36: 5 | F36: 7.5 | G36: =(D36-F36)/F36 -> 0.26666667 | H36: 8.5 | K36: 0.004 | L36: =G36-19% -> 0.076666667
B37: Flumioxazin 48% (0,1) B | C37: Flumioxazin 48% | D37: 34 | E37: 5 | F37: 26 | G37: =(D37-F37)/F37 -> 0.30769231 | H37: 35 | I37: =(H37-F37)/F37 -> 0.34615385 | J37: =G37-I37 -> -0.038461538 | K37: 0.007 | L37: =G37-19% -> 0.11769231
B38: Glufosinato 40 (1,5 – 2,5) C | C38: Glufosinato 40% | D38: 6.1 | E38: 20 | F38: 4.9 | G38: =(D38-F38)/F38 -> 0.24489796 | H38: 9 | I38: =(H38-F38)/F38 -> 0.83673469 | J38: =G38-I38 -> -0.59183673 | K38: 0.004 | L38: =G38-19% -> 0.054897959
B39: Pixxaro (0,3 - 0,4) C | D39: 68.5 | E39: 5 | F39: 57 | G39: =(D39-F39)/F39 -> 0.20175439 | H39: 62 | I39: =(H39-F39)/F39 -> 0.087719298 | J39: =G39-I39 -> 0.11403509 | K39: 0.004 | L39: =G39-19% -> 0.011754386
B40: Saflunex 70 (0,8) C | D40: 220 | E40: 0.35 | F40: 180 | G40: =(D40-F40)/F40 -> 0.22222222 | L40: =G40-19% -> 0.032222222
B41: Strim (1-1,5) B | C41: S-metalacloro 96% | D41: 14 | E41: 20 | F41: 10 | G41: =(D41-F41)/F41 -> 0.4 | H41: 11.5 | I41: =(H41-F41)/F41 -> 0.15 | J41: =G41-I41 -> 0.25 | K41: 0.007 | L41: =G41-19% -> 0.21
B42: Texaro (0,043) C | D42: 546 | E42: 0.86 | F42: 465 | G42: =(D42-F42)/F42 -> 0.17419355 | H42: 520 | I42: =(H42-F42)/F42 -> 0.11827957 | J42: =G42-I42 -> 0.055913978 | K42: 0.004 | L42: =G42-19% -> -0.015806452
...

Sheet Pacote
C3: Cliente | D3: APARECIDO | F3: Cant. Ha | G3: 120
F4: Sacas/Ha | G4: =IF(G16>0.1,G18,"ERRO") -> 7.6906074 | H4: Valor da Saca
F5: Contrato Kg | G5: =IF(G16>=0.1,ROUNDUP(G17*60,0),"ERRO") -> 55373
F6: Total USD | G6: =IF(AND(SUM(D23:D69)>=8,G71>=3),SUM(L23:L69),"ERRO") -> 21125 | H6: =G12 -> 23
F7: Contrato em Aberto Kg | G7: =+G5*1.3 -> 71984.9
G8: Disponivel
G9: Soja 23/24
F10: Total Custo | G10: =SUM(M24:M69) -> 15432.5
F11: Margem | G11: =(G6-G10)/G10 -> 0.36886441
F12: Preco da Soja | G12: 23 | H12: =IF(G11>=X14,X15,IF(G11>=W14,W15,IF(G11>=V14,V15,IF(G11>=U14,U15,IF(G11>=T14,T15,IF(G11>=S14,S15,IF(G11>=R14,R15,IF(G11>=Q14,Q15,IF(G11>=P14,P15,"ERRO"))))))))) -> 22
F13: Preço Livre | G13: =G12-(G12/21*10/100) -> 22.890476 | T13: Margem
F14: Precio real Soja | G14: 19.68 | P14: =P16+P17 -> 0.096 | Q14: =Q16+Q17 -> 0.1321 | R14: =R16+R17 -> 0.1437 | S14: =S16+S17 -> 0.1548 | T14: =T16+T17 -> 0.1664 | U14: =U16+U17 -> 0.1775 | V14: =V16+V17 -> 0.1891 | W14: =W16+W17 -> 0.2002 | X14: =X16+X17 -> 0.2118
F15: DIF Preco Real | G15: =(G12-G14)/G14 -> 0.16869919 | P15: 21 | Q15: 21.12 | R15: 21.25 | S15: 21.37 | T15: 21.5 | U15: 21.62 | V15: 21.75 | W15: 21.87 | X15: 22
F16: Margem | G16: =G11-G15 -> 0.20016522 | H16: =ROUND(G16,4) -> 0.2002 | P16: 0.066 | Q16: 0.0721 | R16: 0.0787 | S16: 0.0848 | T16: 0.0914 | U16: 0.0975 | V16: 0.1041 | W16: 0.1102 | X16: 0.1168
F17: Quantidade de Sacas | G17: =G6/G13 -> 922.87289 | H17: 0.1 | P17: 0.03 | Q17: 0.06 | R17: 0.065 | S17: 0.07 | T17: 0.075 | U17: 0.08 | V17: 0.085 | W17: 0.09 | X17: 0.095
F18: Sa/Ha | G18: =G17/G3 -> 7.6906074 | H18: =H16-H17 -> 0.1002
F19: Lucro Liq. | G19: =G10*G16 -> 3089.0498
O20: =SUM(O31:O69) -> 386.405
C21: ="V."&O20&"." -> V.386,405.
C23: Fert | D23: Aplic. | E23: Produto | F23: Dose/Ha (Kg/Ha) | G23: Cant. Produto | H23: Precio | I23: PREÇO | K23: QUAT. EXATA | L23: U$/AREA | M23: US Custo
C24: Fert | G24: =IF(E24="",0,MROUND(K24,VLOOKUP(E24,Precos!$B$2:$E$13,4,1))) -> 0 | H24: =I24 -> 0 | I24: =IF(E24="",0,VLOOKUP(E24,Precos!$B$2:$E$4,3,1)) -> 0 | J24: =IF(E24="",0,VLOOKUP(E24,Precos!$B$2:$G$4,5,1)) -> 0 | K24: =$G$3*D24*F24 -> 0 | L24: =G24*I24 -> 0 | M24: =G24*J24 -> 0 | N24: =IF(E24="",0,VLOOKUP(E24,Precos!$B$2:$K$4,10,1)) -> 0 | O24: =L24*N24 -> 0
C25: Fert | G25: =IF(E25="",0,MROUND(K25,VLOOKUP(E25,Precos!$B$2:$E$13,4,1))) -> 0 | H25: =I25 -> 0 | I25: =IF(E25="",0,VLOOKUP(E25,Precos!$B$2:$E$4,3,1)) -> 0 | J25: =IF(E25="",0,VLOOKUP(E25,Precos!$B$2:$G$4,5,1)) -> 0 | K25: =$G$3*D25*F25 -> 0 | L25: =G25*I25 -> 0 | M25: =G25*J25 -> 0 | N25: =IF(E25="",0,VLOOKUP(E25,Precos!$B$2:$K$4,10,1)) -> 0 | O25: =L25*N25 -> 0
C26: Fert | G26: =IF(E26="",0,MROUND(K26,VLOOKUP(E26,Precos!$B$2:$E$13,4,1))) -> 0 | H26: =I26 -> 0 | I26: =IF(E26="",0,VLOOKUP(E26,Precos!$B$2:$E$4,3,1)) -> 0 | J26: =IF(E26="",0,VLOOKUP(E26,Precos!$B$2:$G$4,5,1)) -> 0 | K26: =$G$3*D26*F26 -> 0 | L26: =G26*I26 -> 0 | M26: =G26*J26 -> 0 | N26: =IF(E26="",0,VLOOKUP(E26,Precos!$B$2:$K$4,10,1)) -> 0 | O26: =L26*N26 -> 0
C27: Fert | G27: =IF(E27="",0,MROUND(K27,VLOOKUP(E27,Precos!$B$2:$E$13,4,1))) -> 0 | H27: =I27 -> 0 | I27: =IF(E27="",0,VLOOKUP(E27,Precos!$B$2:$E$4,3,1)) -> 0 | J27: =IF(E27="",0,VLOOKUP(E27,Precos!$B$2:$G$4,5,1)) -> 0 | K27: =$G$3*D27*F27 -> 0 | L27: =G27*I27 -> 0 | M27: =G27*J27 -> 0 | N27: =IF(E27="",0,VLOOKUP(E27,Precos!$B$2:$K$4,10,1)) -> 0 | O27: =L27*N27 -> 0
C28: Fert | G28: =IF(E28="",0,MROUND(K28,VLOOKUP(E28,Precos!$B$2:$E$13,4,1))) -> 0 | H28: =I28 -> 0 | I28: =IF(E28="",0,VLOOKUP(E28,Precos!$B$2:$E$4,3,1)) -> 0 | J28: =IF(E28="",0,VLOOKUP(E28,Precos!$B$2:$G$4,5,1)) -> 0 | K28: =$G$3*D28*F28 -> 0 | L28: =G28*I28 -> 0 | M28: =G28*J28 -> 0 | N28: =IF(E28="",0,VLOOKUP(E28,Precos!$B$2:$K$4,10,1)) -> 0 | O28: =L28*N28 -> 0
C29: Fert | G29: =IF(E29="",0,MROUND(K29,VLOOKUP(E29,Precos!$B$2:$E$13,4,1))) -> 0 | H29: =I29 -> 0 | I29: =IF(E29="",0,VLOOKUP(E29,Precos!$B$2:$E$4,3,1)) -> 0 | J29: =IF(E29="",0,VLOOKUP(E29,Precos!$B$2:$G$4,5,1)) -> 0 | K29: =$G$3*D29*F29 -> 0 | L29: =G29*I29 -> 0 | M29: =G29*J29 -> 0 | N29: =IF(E29="",0,VLOOKUP(E29,Precos!$B$2:$K$4,10,1)) -> 0 | O29: =L29*N29 -> 0
C30: Semente | D30: Aplic. | E30: Produto | F30: Dose/Ha (sc de 125mil) | G30: Cant. Produto | H30: Precio | I30: PREÇO | K30: QUAT. EXATA | L30: U$/AREA | M30: US Custo
C31: Semente | D31: 1 | E31: 64IX66 RSF (NEXUS) (235mil/Há) A | G31: =IF(E31="",0,MROUND(K31,VLOOKUP(E31,Precos!$B$6:$E$23,4,1))) -> 0 | H31: =I31 -> 33 | I31: =IF(E31="",0,VLOOKUP(E31,Precos!$B$6:$E$23,3,1)) -> 33 | J31: =IF(E31="",0,VLOOKUP(E31,Precos!$B$6:$G$23,5,1)) -> 23.81 | K31: =$G$3*D31*F31 -> 0 | L31: =G31*I31 -> 0 | M31: =G31*J31 -> 0 | N31: =IF(E31="",0,VLOOKUP(E31,Precos!$B$6:$K$14,10,1)) -> 0.025 | O31: =L31*N31 -> 0
C32: Semente | G32: =IF(E32="",0,MROUND(K32,VLOOKUP(E32,Precos!$B$6:$E$23,4,1))) -> 0 | H32: =I32 -> 0 | I32: =IF(E32="",0,VLOOKUP(E32,Precos!$B$6:$E$23,3,1)) -> 0 | J32: =IF(E32="",0,VLOOKUP(E32,Precos!$B$6:$G$23,5,1)) -> 0 | K32: =$G$3*D32*F32 -> 0 | L32: =G32*I32 -> 0 | M32: =G32*J32 -> 0 | N32: =IF(E32="",0,VLOOKUP(E32,Precos!$B$6:$K$14,10,1)) -> 0 | O32: =L32*N32 -> 0
C33: Semente | G33: =IF(E33="",0,MROUND(K33,VLOOKUP(E33,Precos!$B$6:$E$23,4,1))) -> 0 | H33: =I33 -> 0 | I33: =IF(E33="",0,VLOOKUP(E33,Precos!$B$6:$E$23,3,1)) -> 0 | J33: =IF(E33="",0,VLOOKUP(E33,Precos!$B$6:$G$23,5,1)) -> 0 | K33: =$G$3*D33*F33 -> 0 | L33: =G33*I33 -> 0 | M33: =G33*J33 -> 0 | N33: =IF(E33="",0,VLOOKUP(E33,Precos!$B$6:$K$14,10,1)) -> 0 | O33: =L33*N33 -> 0
C34: Semente | G34: =IF(E34="",0,MROUND(K34,VLOOKUP(E34,Precos!$B$6:$E$23,4,1))) -> 0 | H34: =I34 -> 0 | I34: =IF(E34="",0,VLOOKUP(E34,Precos!$B$6:$E$23,3,1)) -> 0 | J34: =IF(E34="",0,VLOOKUP(E34,Precos!$B$6:$G$23,5,1)) -> 0 | K34: =$G$3*D34*F34 -> 0 | L34: =G34*I34 -> 0 | M34: =G34*J34 -> 0 | N34: =IF(E34="",0,VLOOKUP(E34,Precos!$B$6:$K$14,10,1)) -> 0 | O34: =L34*N34 -> 0
C35: TS | D35: Aplic. | E35: Produto | F35: Dose/Ha (Lt/Kg de sem.) | G35: Cant. Produto | H35: Precio | I35: PREÇO | K35: QUAT. EXATA | L35: U$/AREA | M35: US Custo
C36: TS | D36: 1 | E36: Clorante 62,5 (0,5 ml/Kg) A | F36: 0.03 | G36: =IF(E36="",0,MROUND(K36,VLOOKUP(E36,Precos!$B$25:$E$34,4,1))) -> 5 | H36: =I36 -> 90 | I36: =IF(E36="",0,VLOOKUP(E36,Precos!$B$25:$E$34,3,1)) -> 90 | J36: =IF(E36="",0,VLOOKUP(E36,Precos!$B$25:$G$34,5,1)) -> 60 | K36: =$G$3*D36*F36 -> 3.6 | L36: =G36*I36 -> 450 | M36: =G36*J36 -> 300 | N36: =IF(E36="",0,VLOOKUP(E36,Precos!B25:K34,10,1)) -> 0.01 | O36: =L36*N36 -> 4.5
C37: TS | D37: 1 | E37: Rancona (1 ml/kg) C | F37: 0.04 | G37: =IF(E37="",0,MROUND(K37,VLOOKUP(E37,Precos!$B$25:$E$34,4,1))) -> 5 | H37: =I37 -> 49.5 | I37: =IF(E37="",0,VLOOKUP(E37,Precos!$B$25:$E$34,3,1)) -> 49.5 | J37: =IF(E37="",0,VLOOKUP(E37,Precos!$B$25:$G$34,5,1)) -> 42 | K37: =$G$3*D37*F37 -> 4.8 | L37: =G37*I37 -> 247.5 | M37: =G37*J37 -> 210 | N37: =IF(E37="",0,VLOOKUP(E37,Precos!$B$25:$K$34,10,1)) -> 0.004 | O37: =L37*N37 -> 0.99
C38: TS | D38: 1 | E38: Fertactyl Leg (2 ml/kg) A | F38: 0.08 | G38: =IF(E38="",0,MROUND(K38,VLOOKUP(E38,Precos!$B$25:$E$34,4,1))) -> 10 | H38: =I38 -> 107 | I38: =IF(E38="",0,VLOOKUP(E38,Precos!$B$25:$E$34,3,1)) -> 107 | J38: =IF(E38="",0,VLOOKUP(E38,Precos!$B$25:$G$34,5,1)) -> 79 | K38: =$G$3*D38*F38 -> 9.6 | L38: =G38*I38 -> 1070 | M38: =G38*J38 -> 790 | N38: =IF(E38="",0,VLOOKUP(E38,Precos!$B$25:$K$34,10,1)) -> 0.04 | O38: =L38*N38 -> 42.8
C39: TS | D39: 1 | E39: Rizoliq Top (2 ml/kg) A | F39: 0.08 | G39: =IF(E39="",0,MROUND(K39,VLOOKUP(E39,Precos!$B$25:$E$34,4,1))) -> 10 | H39: =I39 -> 26 | I39: =IF(E39="",0,VLOOKUP(E39,Precos!$B$25:$E$34,3,1)) -> 26 | J39: =IF(E39="",0,VLOOKUP(E39,Precos!$B$25:$G$34,5,1)) -> 16 | K39: =$G$3*D39*F39 -> 9.6 | L39: =G39*I39 -> 260 | M39: =G39*J39 -> 160 | N39: =IF(E39="",0,VLOOKUP(E39,Precos!$B$25:$K$34,10,1)) -> 0.04 | O39: =L39*N39 -> 10.4
C40: TS | G40: =IF(E40="",0,MROUND(K40,VLOOKUP(E40,Precos!$B$25:$E$34,4,1))) -> 0 | H40: =I40 -> 0 | I40: =IF(E40="",0,VLOOKUP(E40,Precos!$B$25:$E$34,3,1)) -> 0 | J40: =IF(E40="",0,VLOOKUP(E40,Precos!$B$25:$G$34,5,1)) -> 0 | K40: =$G$3*D40*F40 -> 0 | L40: =G40*I40 -> 0 | M40: =G40*J40 -> 0 | N40: =IF(E40="",0,VLOOKUP(E40,Precos!$B$25:$K$34,10,1)) -> 0 | O40: =L40*N40 -> 0
C41: TS | G41: =IF(E41="",0,MROUND(K41,VLOOKUP(E41,Precos!$B$25:$E$34,4,1))) -> 0 | H41: =I41 -> 0 | I41: =IF(E41="",0,VLOOKUP(E41,Precos!$B$25:$E$34,3,1)) -> 0 | J41: =IF(E41="",0,VLOOKUP(E41,Precos!$B$25:$G$34,5,1)) -> 0 | K41: =$G$3*D41*F41 -> 0 | L41: =G41*I41 -> 0 | M41: =G41*J41 -> 0 | N41: =IF(E41="",0,VLOOKUP(E41,Precos!$B$25:$K$34,10,1)) -> 0 | O41: =L41*N41 -> 0
C42: HERBICIDAS | D42: Aplic. | E42: Produto | F42: Dose/Ha (Lt ou KgHa) | G42: Cant. Produto | H42: Precio | I42: PREÇO | K42: QUAT. EXATA | L42: U$/AREA | M42: US Custo
C43: HERBICIDAS | E43: Clomazone 48% (0,8 - 1) C | F43: 1 | G43: =IF(E43="",0,MROUND(K43,VLOOKUP(E43,Precos!$B$36:$E$43,4,1))) -> 0 | H43: =I43 -> 9.5 | I43: =IF(E43="",0,VLOOKUP(E43,Precos!$B$36:$E$44,3,1)) -> 9.5 | J43: =IF(E43="",0,VLOOKUP(E43,Precos!$B$36:G$44,5,1)) -> 7.5 | K43: =$G$3*D43*F43 -> 0 | L43: =G43*I43 -> 0 | M43: =G43*J43 -> 0 | N43: =IF(E43="",0,VLOOKUP(E43,Precos!$B$36:$K$42,10,1)) -> 0.004 | O43: =L43*N43 -> 0
...
